<?xml version="1.0"?>

<robot name="test_robot">
    <link name="base_link">
        <visual>
            <geometry>
                <cylinder length="0.6" radius="0.2"/>
            </geometry>
            <origin xyz="0.0 0.0 0.0" rpy="0.0 0.0 0.0"/>
        </visual>
    </link>
    <!-- <joint name="q1" type="revolute">
        <parent link="base_link"/>
        <child link="link_1"/>
        <axis xyz="0 1 0"/>
        <origin xyz="0.0 0.0 0.6" rpy="0 0 0"/>
        <limit lower="-3.14" upper="3.14" effort="0.0" velocity="0.0"/>
    </joint> -->
    <joint name="q1" type="continuous">
        <origin xyz="0.0 0.0 0.3" rpy="0.0 0.0 0.0"/>
        <parent link="base_link"/>
        <child link="link_1"/>
        <axis xyz="0 1 0"/>
    </joint>
    <!-- <joint name="q1" type="fixed">
        <parent link="base_link"/>
        <child link="link_1"/>
        <origin xyz="0.0 0.0 0.3" rpy="0.0 0.0 0.0"/>
    </joint> -->
    <link name="link_1">
        <visual>
            <geometry>
                <cylinder length="1.0" radius="0.2"/>
            </geometry>
            <origin xyz="0.0 0.0 0.5" rpy="0.0 0.0 0.0"/>
        </visual>
    </link>
</robot>